2021/11/03 16:02:39 | python_logging.py(83 行) | INFO| 开始记录执行开始时间-------
2021/11/03 16:02:40 | python_logging.py(83 行) | INFO| 执行一共花费0.01139974594116211秒-------
2021/11/03 16:02:40 | python_logging.py(83 行) | INFO| 开始记录执行开始时间-------
2021/11/03 16:02:41 | python_logging.py(87 行) | ERROR| 执行函数过程中出错，错误原因为自己加的报错！！
